Workbook
Name capini: #REF!
Name capini2: #REF!
Name cm: #REF!
Name cm_2: #REF!
Name cotiz_inicial: #REF!
Name cotiz_inicial2: #REF!
Name i_cob_men: #REF!
Name i_m: #REF!
Name i_m2: #REF!
Name plazo: #REF!
Name plazo2: #REF!
Name sistema_valido: #REF!
Name sistema_valido2: #REF!
Name tasa_mv: #REF!
Name tasa_mv2: #REF!
Name tasa_upacs: #REF!
Name tasa_upacs2: #REF!
Name capini: [1]ACTUAL!$A$11
Name cm: [1]ACTUAL!$A$13
Name cotiz_inicial: [1]ACTUAL!$A$12
Name i_m: [1]ACTUAL!$A$8
Name plazo: [1]ACTUAL!$A$5
Name sistema_valido: [1]ACTUAL!$K$5
Name tasa_mv: [1]ACTUAL!$A$6
Name tasa_upacs: [1]ACTUAL!$A$7
Name capini: [1]ACTUAL!$A$11
Name cm: [1]ACTUAL!$A$13
Name cotiz_inicial: [1]ACTUAL!$A$12
Name i_m: [1]ACTUAL!$A$8
Name plazo: [1]ACTUAL!$A$5
Name sistema_valido: [1]ACTUAL!$K$5
Name tasa_mv: [1]ACTUAL!$A$6
Name tasa_upacs: [1]ACTUAL!$A$7
Name capini: [1]ACTUAL!$A$11
Name capini2: #REF!
Name cm: [1]ACTUAL!$A$13
Name cm_2: #REF!
Name cotiz_inicial: [1]ACTUAL!$A$12
Name cotiz_inicial2: #REF!
Name i_cob_men: #REF!
Name i_m: [1]ACTUAL!$A$8
Name i_m2: #REF!
Name plazo: [1]ACTUAL!$A$5
Name plazo2: #REF!
Name sistema_valido: [1]ACTUAL!$K$5
Name sistema_valido2: #REF!
Name tasa_mv: [1]ACTUAL!$A$6
Name tasa_mv2: #REF!
Name tasa_upacs: [1]ACTUAL!$A$7
Name tasa_upacs2: #REF!

Sheet BD
A1: Nombre | B1: # Crédito | C1: Solicitud Creada | D1: Estado | E1: Completo info | F1: BANCO | G1: Nota de Consultor o Cliente | H1: Referenciador | I1: Nota CRM | J1: NOTAS | K1: Creación Nota | L1: Equipo | M1: Consultor | N1: Cronograma - Start | O1: Cronograma - End | P1: Estudio | Q1: Extracto | R1: CC | S1: AMORTIZA | T1: Tipo | U1: Cuota Mensual | V1: P. Inicial | W1: P. Pendiente | X1: Tasa | Y1: Frech | Z1: S. Vida | AA1: S. Incendio | AB1: S. Terremoto | AC1: Capital Mensual | AD1: Interés Mensual | AE1: Capital Adeudado | AF1: Abono Efectivo | AG1: Ingresos demostrables | AH1: Actividad Económica | AI1: E-mail | AJ1: Teléfono | AK1: Ciudad | AL1: Acuerdos | AM1: Cuentas (equipos) | AN1: ID de registro | AO1: Mensaje
A2: 1 | B2: 2 | C2: 3 | D2: 4 | E2: 5 | F2: 6 | G2: 7 | H2: 8 | I2: 9 | J2: 10 | K2: 11 | L2: 12 | M2: 13 | N2: 14 | O2: 15 | P2: 16 | Q2: 17 | R2: 18 | S2: 19 | T2: 20 | U2: 21 | V2: 22 | W2: 23 | X2: 24 | Y2: 25 | Z2: 26 | AA2: 27 | AB2: 28 | AC2: 29 | AD2: 30 | AE2: 31 | AF2: 32 | AG2: 33 | AH2: 34
A3: MIGUEL ARTURO CUBILLOS ESCOBAR | B3: 90000118327 | F3: BANCOLOMBIA | S3: PESOS | T3: Hipotecario | U3: 692611.56 | V3: 180 | W3: 118 | X3: 0.107 | Y3: 190228 | Z3: 11174 | AA3: 11976 | AB3: 7984 | AC3: 353667.39 | AD3: 307810.17 | AE3: 58056655
A4: RICARDO LEON CANO CARDONA | B4: 571313330002772 | F4: DAVIVIENDA | S4: PESOS | T4: HIPOTECARIO | U4: 916000 | V4: 240 | W4: 234 | X4: 0 | Y4: 0 | Z4: 25098 | AA4: 26680 | AB4: 0 | AC4: 105994 | AD4: 758006 | AE4: 84554959 | AI4: ricardocano997@gmail.com
A5: MARISOL BECERRA GARCIA | B5: 133201685628 | F5: BANCO CAJA SOCIAL | M5: Brillid Lorena Salinas Perdomo | S5: PESOS | U5: 1533100 | V5: 240 | W5: 236 | X5: 0.108 | Z5: 76918 | AA5: 30000 | AB5: 26972 | AC5: 184598 | AD5: 1214612 | AE5: 141513584 | AF5: 350000 | AG5: 4000000 | AH5: Pensionado | AK5: Bogota
A6: SONIA CAROLINA MENDOZA FERNANDEZ | B6: 57000740112493 | F6: DAVIVIENDA | M6: Nelly Roa | S6: PESOS | U6: 1686000 | V6: 160 | W6: 113 | X6: 0.0243 | AC6: 1340649 | AD6: 345351 | AE6: 171257874 | AF6: 200000 | AG6: 8000000 | AH6: Empleado | AK6: Bogota | AM6: El crédito tuvo disminución de tiempo por proceso de insolvencia persona natural en el año 2022
A7: ANGIE NATHALIA ZULUAGA OSORIO | B7: 570048910005995 | F7: DAVIVIENDA | M7: Paula Osorno | S7: PESOS | T7: HIPOTECARIO | U7: 626000 | V7: 240 | W7: 187 | X7: 0.095 | Y7: 177749 | Z7: 46092 | AA7: 30630 | AC7: 132269 | AD7: 234828 | AE7: 54375853 | AF7: 400000 | AG7: 6100000 | AH7: Empleado | AI7: angie.zuluaga22@gmail.com | AK7: Teruel
A8: JHEFREE SINISTERRA PEDROZA | B8: 570101700060099 | F8: DAVIVIENDA | M8: Paula Osorno | S8: PESOS | T8: HIPOTECARIO | U8: 1165000 | V8: 240 | W8: 200 | X8: 0.1455 | Z8: 19237 | AA8: 29504 | AC8: 149673 | AD8: 992909 | AE8: 87290356 | AF8: 100000 | AG8: 500000 | AH8: Empleado | AI8: jhefree1@hotmail.com | AK8: Toronto
A9: JHON ALEXANDER PERALTA SANCHEZ | B9: 204119067975 | D9: ALTA | E9: 204119067975 | F9: COLPATRIA | H9: PROPIO | I9: FALTA PERFILAMIENTO | L9: Guardianes Del Ahorro | M9: Jhon Fredy Garcia Pardo | R9: 14298138 | S9: Pesos | T9: Hipotecario | U9: 5449364 | V9: 180 | W9: 128 | X9: 7.49 | Y9: 0 | Z9: 313664 | AA9: 0 | AB9: 0 | AC9: 2481049 | AD9: 2654650 | AE9: 466940176 | AF9: $900.000 a $1.200.000 | AG9: $43,603,000 | AH9: Empleado | AI9: PERALTAJHON@GMAIL.COM | AJ9: 3166289503
A10: HEIDY ROJAS MENDOZA | B10: 530200069444 | C10: https://app.hubspot.com/contacts/21065449/record/0-1/158827019187 | D10: NORMAL | E10: 530200069444 | F10: CAJA SOCIAL | R10: 60369868 | S10: Pesos | T10: Hipotecario | U10: 1633900 | V10: 183 | W10: 115 | X10: 8.5% | Y10: 0 | Z10: 155515 | AA10: 16615 | AB10: 14939 | AC10: 657701 | AD10: 789129 | AE10: 115682836 | AF10: 300 | AG10: $4,000,000 | AH10: Empleado | AI10: hhrm75@gmail.com | AJ10: 3156768371
A11: ENDER EXGLIS CUELLO AVILA | B11: 570303600581154-5 | C11: https://app.hubspot.com/contacts/21065449/record/0-1/124528151925 | D11: ALTA | E11: 570303600581154-5 | F11: DAVIVIENDA | G11: Buen día, sí yo lo envié de todas formas ayer viernes reenvié el correo, por favor su ayuda porque el cliente desea verlo lunes. Reagendamos para este lunes. Saludos. | H11: CM | K11: 45804 | L11: Visionarios | M11: PAOLA HERNANDEZ | N11: 45805 | P11: https://tinyurl.com/48hutwxa | R11: 1127616613 | S11: Pesos | T11: Hipotecario | U11: 3290000 | V11: 131 | W11: 124 | X11: 0.14 | Y11: 0 | Z11: 0 | AA11: 0 | AB11: 0 | AC11: 838615 | AD11: 2453702 | AE11: 222972490 | AF11: 710 | AG11: $25,000,000 | AH11: Empleado | AI11: ender1654@gmail.com | AJ11: 19292756652 | AK11: EEUU | AN11: EEUU
A12: JENNY ANDREA GOMEZ JIMENEZ | B12: 5389218315 | D12: NORMAL | E12: 5389218315 | F12: FNA (Fondo Nacional del Ahorro) | H12: PROPIO | L12: Finanzas a otro nivel | M12: CAROLINA MORA | R12: 53892183 | S12: Pesos | T12: Hipotecario | U12: 337382 | V12: 240 | W12: 239 | X12: 0.15 | Y12: 156798 | Z12: 58218 | AA12: 0 | AB12: 0 | AC12: 0 | AD12: 0 | AE12: 36257024 | AF12: 50-300 | AG12: $1,600,000 | AH12: Empleado | AI12: jennygomez0883@gmail.com | AJ12: 3219166515
A13: ANYELI PATRICIA COLMENARES CLAVIJO | B13: 600000040022888-5 | C13: https://app.hubspot.com/contacts/21065449/record/0-1/158887871152 | D13: NORMAL | E13: 600000040022888-5 | F13: DAVIVIENDA | H13: CM | L13: Soluciones Financieras | M13: LORENA SALINAS | R13: N/A | S13: Pesos | T13: Leasing H. | U13: 1827000 | V13: 240 | W13: 116 | X13: 10.5% | Y13: 0 | Z13: 211814 | AA13: 121735 | AB13: 0 | AC13: 537302 | AD13: 956697 | AE13: 114504154 | AF13: 200 | AG13: $12,000,000 | AH13: Empleado | AI13: anyelipcc@hotmail.com | AJ13: 3106793820 | AK13: BOGOTA | AN13: BOGOTA
A14: JAZMIN ESPERANZA RODRIGUEZ TORRES | B14: 90000348676 | C14: 46025 | D14: Pendiente | E14: 46025 | F14: BANCOLOMBIA | H14: PROPIO | L14: Finanzas a otro nivel | M14: DORA ROMERO | R14: 1071628722 | S14: Pesos | T14: Hipotecario | U14: 1522982 | V14: 240 | W14: 234 | X14: 12.6% | Y14: 0 | Z14: 22343 | AA14: 13275 | AB14: 8849 | AC14: 144727 | AD14: 1070710 | AE14: 134816357 | AF14: $900.000 a $1.200.000 | AG14: $15,000,000 | AH14: Empleado | AI14: mazdajazmin19@yahoo.es | AJ14: 3112943691 | AK14: BOGOTA | AN14: IBAGUE
A15: LINA MARIA MENESES MEJIA | B15: 555842602 | C15: 46070 | D15: Pendiente | E15: 46077 | F15: BANCO DE BOGOTA | G15: Buenas tardes, envío perfilamiento de la cliente del asunto para que puedan elaborar el estudio financiero. Gracias Paula O. | H15: CM | O15: 46070 | R15: N/A | S15: Pesos | T15: Hipotecario | U15: 425560 | V15: 240 | W15: 146 | X15: 7.47% | Y15: 126189 | Z15: 12858 | AA15: 15945 | AB15: 0 | AC15: 37036 | AD15: 485909 | AE15: 38818272 | AF15: 300 | AG15: $3,500,000 | AH15: Empleado | AI15: linammm467@gmail.com | AJ15: 3169935900 | AK15: CALI | AN15: MOSQUERA
A16: SANTIAGO GONZALEZ NARVAEZ | B16: 108833163609 | C16: 46070 | D16: Pendiente | E16: 46077 | F16: FNA (Fondo Nacional del Ahorro) | G16: Buenas tardes, envío perfilamiento del cliente del asunto para que puedan elaborar el estudio financiero. Está en capacidad de incrementar a capital hasta $730.000 Gracias Paula O. | H16: CM | I16: Falta perfilamiento - FNA | O16: 46070 | R16: N/A | S16: Pesos | T16: Hipotecario | U16: 1024713 | V16: 168 | W16: 149 | X16: 9.8% | Y16: 0 | Z16: 53808 | AA16: 0 | AB16: 0 | AC16: 305678 | AD16: 657640 | AE16: 83552192 | AF16: 730 | AG16: $5,800,000 | AH16: Empleado | AI16: juanma.gn7@gmail.com | AJ16: 316 4045943 | AK16: PEREIRA | AN16: BOGOTA
A17: JHEFREE SINISTERRA PEDROZA | B17: 570101700060099-4 | C17: 46077 | D17: Pendiente | E17: 46077 | F17: DAVIVIENDA | H17: CM | L17: Finanzas a otro nivel | M17: Paula Osorno | S17: Pesos | T17: Hipotecario | U17: 1165000 | V17: 240 | W17: 200 | X17: 14.55% | Y17: 0 | Z17: 19237 | AA17: 29504 | AB17: 0 | AC17: 149672 | AD17: 992908 | AE17: 87290355 | AF17: 100 | AG17: 500 | AH17: Empleado | AI17: jhefree1@hotmail.com | AJ17: 1 416-556-4497 | AK17: Toronto
A18: SONIA CAROLINA MENDOZA | B18: 570000740112493-5 | C18: 46077 | D18: Pendiente | E18: 46077 | F18: DAVIVIENDA | G18: El crédito tuvo disminución de tiempo por proceso de insolvencia persona natural en el año 2022 | H18: CM | L18: Finanzas a otro nivel | M18: Nelly Roa | S18: Pesos | T18: Hipotecario | U18: 1686000 | V18: 160 | W18: 113 | X18: 2.43% | Y18: 0 | Z18: 0 | AA18: 0 | AB18: 0 | AC18: 1340648 | AD18: 345351 | AE18: 171257873 | AF18: 200 | AG18: $8,000,000 | AH18: Empleado | AI18: soniacarolina13@hotmail.com | AJ18: 316 2351262 | AK18: Bogotá
A19: ANDRES FELIPE SUAREZ SANCHEZ | B19: 570303960032558-0 | C19: 46077 | D19: Pendiente | E19: 46077 | F19: DAVIVIENDA | G19: Buenas tardes, envío extracto de crédito de remodelación que el cliente tiene en Davivienda del cual desea revisar las propuestas de ahorro. Se adjunta perfilamiento por ser crédito Davivienda. Favor elaborar propuestas con incremento a capital de $500.000 Gracias Paula O. | H19: CM | L19: Finanzas a otro nivel | M19: PAULA OSORNO | R19: N/A | S19: Pesos | T19: Remodelación | U19: 1367000 | V19: 180 | W19: 159 | X19: 0.16 | Y19: 0 | Z19: 0 | AA19: 0 | AB19: 0 | AC19: 200682 | AD19: 1166317 | AE19: 96430697 | AF19: 500 | AG19: $21,000,000 | AH19: Empleado | AI19: afsuarez@gmail.com | AJ19: 317 8929049 | AK19: MEDELLIN
A20: DACIR HERNANDO PORRAS LOZANO | B20: 90000350544 | C20: 46077 | D20: Pendiente | E20: 46077 | F20: BANCOLOMBIA | H20: PROPIO | L20: Visionarios | M20: DANIEL FERNANDEZ | R20: 79444169 | S20: Pesos | T20: Hipotecario | U20: 2289327 | V20: 240 | W20: 232 | X20: 0.14 | Y20: 0 | Z20: 110595 | AA20: 28479 | AB20: 18985 | AC20: 167393 | AD20: 1963874 | AE20: 179280180 | AF20: $100.000 a $300.000 | AG20: $12,000,000 | AH20: Empleado | AI20: hormigalider@hotmail.com | AJ20: 3142860450
A21: DIANA CAROLINA FORERO AGUILERA | B21: 1058595794 | C21: 46077 | D21: Pendiente | E21: 46077 | F21: BANCO DE BOGOTA | H21: PROPIO | L21: Visionarios | M21: MARIELA BECERRA | R21: 1098689019 | S21: Pesos | T21: Hipotecario | U21: 3021414 | V21: 120 | W21: 113 | X21: 12.14% | Y21: 0 | Z21: 47152 | AA21: 70216 | AB21: 0 | AC21: 977260 | AD21: 1926784 | AE21: 201851655 | AF21: $100.000 a $300.000 | AG21: $8,000,000 | AH21: Empleado | AI21: karo_sjj@hotmail.com | AJ21: 3150010171
A22: LAURA CATALINA ROSAS | B22: 204160001387 | C22: 46078 | D22: Pendiente | F22: COLPATRIA | H22: CM | I22: Falta perfilamiento - Colpatria | L22: Finanzas a otro nivel | M22: Nelly Roa | O22: 46078 | R22: N/A | S22: Pesos | T22: Hipotecario | U22: 881610 | V22: 288 | W22: 275 | X22: 8.09 | Y22: 0 | Z22: 65534 | AA22: 0 | AB22: 0 | AC22: 136349 | AD22: 679726 | AE22: 104373899 | AF22: 100 | AG22: $3,000,000 | AH22: Empleado | AI22: rosaslaura438@gmail.com | AJ22: 302 8394990 | AK22: Bogota
A23: LUZ DARY AVELLA FLOREZ | B23: 571717640003982-3 | C23: 46077 | D23: Mora | E23: 46077 | F23: DAVIVIENDA | H23: CM | L23: Soluciones Financieras | M23: Miryam Roa | R23: N/A | S23: Pesos | T23: Hipotecario | U23: 654521 | V23: 180 | W23: 69 | X23: 12.75% | Y23: 122479 | Z23: 59302 | AA23: 0 | AB23: 0 | AC23: 123584 | AD23: 379404 | AE23: 37750239 | AF23: 600 | AG23: $6,000,000 | AH23: Empleado | AI23: lalys.16_88@hotmail.com | AJ23: 310 2298521 | AK23: Sogamoso
A24: TATIANA ANDREA RENGIFO ARBOLEDA | B24: 90000298802 | C24: 46077 | D24: Pendiente | E24: 46077 | F24: BANCOLOMBIA | H24: CM | L24: Finanzas a otro nivel | M24: Paula Osorno | R24: 1061768300 | S24: Pesos | T24: Hipotecario | U24: 698226 | V24: 240 | W24: 223 | X24: 6.75% | Y24: 284334 | Z24: 9816 | AA24: 8300 | AB24: 5533 | AC24: 199196 | AD24: 475381 | AE24: 87128458 | AF24: 300 | AG24: $35,000,000 | AH24: Empleado | AI24: tatirengifo1234@gmail.com | AJ24: 312 8605123 | AK24: Popayan
A25: LAURA CATALINA ROSAS | B25: 204160001387 | C25: 46078 | D25: Pendiente | F25: COLPATRIA | H25: CM | I25: Falta perfilamiento - Colpatria | L25: Finanzas a otro nivel | M25: Nelly Roa | O25: 46078 | R25: N/A | S25: Pesos | T25: Hipotecario | U25: 881610 | V25: 288 | W25: 275 | X25: 8.09 | Y25: 0 | Z25: 65534 | AA25: 0 | AB25: 0 | AC25: 136349 | AD25: 679726 | AE25: 104373899 | AF25: 100 | AG25: $3,000,000 | AH25: Empleado | AI25: rosaslaura438@gmail.com | AJ25: 302 8394990 | AK25: Bogota
A26: NATHALY COBO MENDEZ | B26: 90000025146 | C26: 46077 | D26: Pendiente | E26: 46077 | F26: BANCOLOMBIA | H26: CM | I26: Falta perfilamiento - Bogota | L26: Guardianes Del Ahorro | M26: Sandra Patricia Moreno | R26: 31710094 | S26: Pesos | T26: Hipotecario | U26: 1796207 | V26: 183 | W26: 88 | X26: 10.15% | Y26: 0 | Z26: 53506 | AA26: 25871 | AB26: 17247 | AC26: 829778 | AD26: 869804 | AE26: 109355204 | AF26: 300 | AG26: $5,000,000 | AH26: Empleado | AI26: cobomendeznathaly@gmail.com | AJ26: 3147573314 | AK26: cali
A27: KELLY JOHANNA MUÑOZ BONILLA | B27: 90000384420 | C27: 46077 | D27: Pendiente | E27: 46077 | F27: BANCOLOMBIA | H27: CM | L27: Soluciones Financieras | M27: Lorena Salinas | R27: 1110548178 | S27: Pesos | T27: Hipotecario | U27: 1456630 | V27: 240 | W27: 239 | X27: 12.6% | Y27: 0 | Z27: 14513 | AA27: 17019 | AB27: 11345 | AC27: 131706 | AD27: 1282047 | AE27: 130025090 | AF27: 200 | AG27: $5,000,000 | AH27: Empleado | AI27: kelly_johannamunoz@hotmail.com | AJ27: 3053171990 | AK27: ibague
A28: JONATHAN ALEXANDER GUERRERO CARDENAS | B28: 570119460026688-8 | C28: 46078 | D28: Pendiente | E28: 46078 | F28: DAVIVIENDA | H28: CM30 | L28: Finanzas a otro nivel | M28: NELLY JANETH ROA GONZALEZ | R28: 1118307343 | S28: Pesos | T28: Hipotecario | U28: 506604 | V28: 240 | W28: 208 | X28: 0.14 | Y28: 209395 | Z28: 11165 | AA28: 15660 | AB28: 38606 | AC28: 65890 | AD28: 355185 | AE28: 51482297 | AF28: Acorde al estado del Crédito | AG28: $3,500,000 | AH28: Vis Davivienda | AI28: Jonathang1901lo@gmail.com | AJ28: 3168723012
A29: KATHERYN CORTES REINEL | B29: 90000387917 | C29: 46042 | D29: Pendiente | E29: 46042 | F29: BANCOLOMBIA | H29: CM | L29: Soluciones Financieras | M29: LORENA SALINAS | R29: 1022370683 | S29: Pesos | T29: Hipotecario | U29: 2537632 | V29: 240 | W29: 240 | X29: 12.25% | Y29: 0 | Z29: 31248 | AA29: 33128 | AB29: 22084 | AC29: 0 | AD29: 0 | AE29: 229054767 | AF29: 200 | AG29: $8,000,000 | AH29: Empleado | AI29: katheryncortes91@gmail.com | AJ29: 316 2522227
A30: ELKIN ENRIQUE JIMENEZ PICO | B30: 600505710036190-8 | C30: 46042 | D30: Pendiente | E30: 46042 | F30: DAVIVIENDA | H30: CM | L30: Soluciones Financieras | M30: MIRYAM ROA | R30: N/A | S30: Pesos | T30: Leasing H. | U30: 2572000 | V30: 240 | W30: 190 | X30: 9.2% | Y30: 0 | Z30: 63079 | AA30: 98736 | AB30: 0 | AC30: 598163 | AD30: 1812021 | AE30: 246283254 | AF30: 300 | AG30: $12,000,000 | AH30: Empleado | AI30: e-medical@hotmail.com | AJ30: 314 6203780
A31: CAMILO ANDRES RODRIGUEZ RINTHA | B31: 556143795 | C31: 46042 | D31: Pendiente | E31: 46042 | F31: BANCO DE BOGOTA | H31: CM | I31: Falta perfilamiento - Bogota | L31: Soluciones Financieras | M31: MIRYAM ROA | N31: 46042 | R31: 80235165 | S31: Pesos | T31: Hipotecario | U31: 662838 | V31: 240 | W31: 175 | X31: 6.34% | Y31: 223117 | Z31: 42679 | AA31: 30100 | AB31: 0 | AC31: 216233 | AD31: 596943 | AE31: 68441988 | AF31: 600 | AG31: $3,700,000 | AH31: Empleado | AI31: carr80@gmail.com | AJ31: 318 6063311 | AK31: BOGOTA
A32: SOL VALENTINA QUINTERO RINCON | B32: 90000347639 | C32: 46042 | D32: Pendiente | E32: 46042 | F32: BANCOLOMBIA | H32: CM | L32: Soluciones Financieras | M32: LORENA SALINAS | R32: N/A | S32: Pesos | T32: Hipotecario | U32: 1563871 | V32: 300 | W32: 288 | X32: 13.2% | Y32: 0 | Z32: 12002 | AA32: 18395 | AB32: 12263 | AC32: 81409 | AD32: 1439801 | AE32: 139061936 | AF32: 100 | AG32: $3,000,000 | AH32: Empleado | AI32: solvalentina98qr@gmail.com | AJ32: 313 4687515
A33: JOHANA VANESA SALAMANCA NIETO | B33: 90000305191 | C33: 46042 | D33: Pendiente | E33: 46042 | F33: BANCOLOMBIA | H33: CM | L33: Soluciones Financieras | M33: MIRYAM ROA | R33: 43985585 | S33: Pesos | T33: Hipotecario | U33: 721559 | V33: 240 | W33: 206 | X33: 7.81% | Y33: 257375 | Z33: 14257 | AA33: 14533 | AB33: 9688 | AC33: 187384 | AD33: 86824 | AE33: 79016882 | AF33: 200 | AH33: Empleado | AI33: johana.salamanca@hotmail.com | AJ33: 239-785-0638
A34: ANGELICA MARIA DAZA GARCIA | B34: 570101240017513-5 | C34: 46042 | D34: Pendiente | E34: 46042 | F34: DAVIVIENDA | H34: CM | L34: Soluciones Financieras | M34: LORENA SALINAS | R34: 31657568 | S34: Pesos | T34: Hipotecario | U34: 585000 | V34: 240 | W34: 186 | X34: 9.5% | Y34: 0 | Z34: 6373 | AA34: 21380 | AB34: 32560 | AC34: 5747837 | AD34: 193362 | AE34: 19979097 | AF34: 500 | AG34: $3,000,000 | AH34: Empleado | AI34: angelicadaza0324@gmail.com | AJ34: 34 686 53 48 52 | AK34: BUGA
A35: JUAN DAVID ROJAS ARANGO | B35: 570101600492052-3 | C35: 46042 | D35: Pendiente | E35: 46042 | F35: DAVIVIENDA | H35: CM | L35: Soluciones Financieras | M35: LORENA SALINAS | R35: N/A | S35: Pesos | T35: Hipotecario | U35: 1481000 | V35: 240 | W35: 236 | X35: 11.6% | Y35: 0 | Z35: 32299 | AA35: 0 | AB35: 0 | AC35: 166675 | AD35: 1282025 | AE35: 139493742 | AF35: 500 | AG35: $10,000,000 | AH35: Empleado | AI35: rojasjuandavid1993@gmail.com | AJ35: 41 78 323 92 90
A36: KAREN LORENA MARTINEZ ALDANA | B36: 1153447640 | C36: 46042 | D36: Pendiente | E36: 46042 | F36: BANCO DE BOGOTA | H36: PROPIO | L36: Finanzas a otro nivel | M36: NELLY ROA | R36: 22733410 | S36: Pesos | T36: Hipotecario | U36: 2257738 | V36: 240 | W36: 237 | X36: 12.38% | Y36: 0 | Z36: 124858 | AA36: 48611 | AB36: 0 | AC36: 205580 | AD36: 1878687 | AE36: 193270229 | AF36: 200000 A 1000000 | AG36: $11,400,000 | AH36: Empleado | AI36: CHICAKAREN2003@HOTMAIL.COM | AJ36: 3104746656
A37: CARLOS YESID SANDOVAL MURILLO | B37: 571616620028788-9 | C37: 46042 | D37: Pendiente | E37: 46042 | F37: DAVIVIENDA | H37: VK 25% | L37: Lideres del futuro | M37: Olga Lucía Avella Rodríguez | R37: 1105671879 | S37: Pesos | T37: Hipotecario | U37: 738000 | V37: 240 | W37: 157 | X37: 0.12 | Y37: 0 | Z37: 27917 | AA37: 54060 | AB37: 0 | AC37: 309878 | AD37: 1082725 | AE37: 57759096 | AF37: $300.000 a $600.000 | AG37: $5,100,000 | AH37: Empleado | AI37: car.yet105@live.com | AJ37: 3214094791
A38: GUZMAN GARZON VARGAS | B38: 90000048107 | C38: 46042 | D38: Pendiente | E38: 46042 | F38: BANCOLOMBIA | H38: VK 25% | L38: Guardianes Del Ahorro | M38: Sandra Patricia Moreno Sotelo | R38: 79256432 | S38: Pesos | T38: Hipotecario | U38: 814332 | V38: 247 | W38: 160 | X38: 0.11 | Y38: 0 | Z38: 58554 | AA38: 12279 | AB38: 8186 | AC38: 177226 | AD38: 558920 | AE38: 67697178 | AF38: $300.000 a $600.000 | AG38: $2,600,000 | AH38: Empleado | AI38: gugarzonuv@unal.edu.co | AJ38: 3105857766
A39: ANA MARIA REYES RESTREPO | B39: 600101790036272-4 | C39: 46042 | D39: Pendiente | E39: 46042 | F39: DAVIVIENDA | H39: PROPIO | L39: Finanzas a otro nivel | M39: ANA MARIA REYES RETREPO | R39: 31927650 | S39: Pesos | T39: Leasing H. | U39: 2413000 | V39: 240 | W39: 225 | X39: 10.95% | Y39: 0 | Z39: 165316 | AA39: 69556 | AB39: 0 | AC39: 1048723 | AD39: 1814404 | AE39: 208110071 | AF39: 200000 A 700000 | AG39: $10,000,000 | AH39: Empleado | AI39: amreyes@termovapor.com | AJ39: 3158172080
A40: ROBERT RIVERA OJEDA | B40: 570101610028578-9 | C40: 46042 | D40: Pendiente | E40: 46042 | F40: DAVIVIENDA | H40: CM30 | L40: Soluciones Financieras | M40: LORENA SALINAA | R40: 285789 | S40: Pesos | T40: Hipotecario | U40: 502000 | V40: 240 | W40: 159 | X40: 0.1 | Y40: 0 | Z40: 9252 | AA40: 27901 | AB40: 0 | AC40: 317476 | AD40: 148370 | AE40: 18683935 | AF40: $300.000 a $600.000 | AG40: $5,600,000 | AH40: Independiente | AI40: roberthrivera_09@hotmail.com | AJ40: 3015313049
...

Sheet ACTUAL
A1: DATA PESOS | E1: =(TODAY()) | G1: SISTEMA | H1: PESOS | J1: CUOTA MENSUAL | K1: =B5
A2: CREDITO N° | B2: 600404220009623-3 | C2: SIMULADOR | E2: =B2 | G2: DINERO PAGADO | H2: =G5*K1 | J2: INTERES MENSUAL | K2: =B14
A3: Titular | B3: =INDEX(Tabla_BD[#All],MATCH(B2,Tabla_BD[[#All],['# Crédito]],0),1) | E3: =B3 | G3: FRECH | H3: =B9 | J3: CAPITAL MENSUAL | K3: =B13
A4: Banco | B4: =INDEX(Tabla_BD[#All],MATCH(B2,Tabla_BD[[#All],['# Crédito]],0),6) | E4: =B4 | G4: =B6 | H4: PLAZO TOTAL | I4: PENDIENTES | J4: PAGAS
A5: Cuota | B5: =INDEX(Tabla_BD[#All],MATCH(B2,Tabla_BD[[#All],['# Crédito]],0),21) | C5: =K19-B9 | F5: PAGAS | G5: =G4-G9 | H5: =G4 | I5: =G9 | J5: =H5-I5
A6: Plazo Total | B6: =INDEX(Tabla_BD[#All],MATCH(B2,Tabla_BD[[#All],['# Crédito]],0),22) | C6: =B6/12 | D6: CUOTAS PAG | E6: TASA E.A | G6: =B8 | H6: PROYECCIONES | I6: AÑOS | J6: MESES | K6: 12 | M6: VARIACION Cta
A7: Plazo Pendiente | B7: =INDEX(Tabla_BD[#All],MATCH(B2,Tabla_BD[[#All],['# Crédito]],0),23) | C7: =B7/12 | D7: =J5 | E7: SALDO CAPITAL | G7: =B15 | H7: OPCION 1 | I7: =B16 | J7: =I7*K6 | M7: =(K1+H3)-K19
A8: Tasa Cobrada | B8: =INDEX(Tabla_BD[#All],MATCH(B2,Tabla_BD[[#All],['# Crédito]],0),24) | C8: DECIMAL COLPATRIA | D8: PLAZO T.N. | E8: TASA DE INTERES MES | G8: =K14 | H8: OPCION 2 | I8: =B17 | J8: =I8*K6
A9: Frech | B9: =INDEX(Tabla_BD[#All],MATCH(B2,Tabla_BD[[#All],['# Crédito]],0),25) | D9: =(D7/12)+B21 | E9: PLAZO PENDIENTE | G9: =B7 | H9: OPCION 3 | I9: =B18 | J9: =I9*K6
A10: Seguro de Vida | B10: =INDEX(Tabla_BD[#All],MATCH(B2,Tabla_BD[[#All],['# Crédito]],0),26) | C10: =SUM(B10+B11+B12+B13+B14) | E10: Edad Cliente | G10: 0 | H10: OPCION 4 | I10: =B19 | J10: =I10*K6
A11: Seguro Incendio | B11: =INDEX(Tabla_BD[#All],MATCH(B2,Tabla_BD[[#All],['# Crédito]],0),27) | C11: SUMA CUOTA | D11: DIF.SIMULA | E11: Valor Inmueble | G11: 0 | H11: OPCION 5 | I11: =B20 | J11: =I11*K6
A12: Seguro Terremoto | B12: =INDEX(Tabla_BD[#All],MATCH(B2,Tabla_BD[[#All],['# Crédito]],0),28) | C12: =B5-C10 | D12: =B24 | E12: Total seguros | G12: =G13+G14 | H12: OPCION 6 | I12: =B21 | J12: =I12*K6
A13: Capital Extracto | B13: =INDEX(Tabla_BD[#All],MATCH(B2,Tabla_BD[[#All],['# Crédito]],0),29) | C13: =G19 | D13: =IF(OR(B4=B33, B23=A32), 0.39, 0.29) | E13: Seguro de Vida | G13: =B10
A14: Intereses Extracto | B14: =INDEX(Tabla_BD[#All],MATCH(B2,Tabla_BD[[#All],['# Crédito]],0),30) | C14: =H19 | E14: Incendio y Terremoto sin iva | G14: =(B11+B12) | H14: TASA NOMINAL MV | K14: =+(1+K16)^(0.0833333333333333)-1
A15: Saldo Capital | B15: =INDEX(Tabla_BD[#All],MATCH(B2,Tabla_BD[[#All],['# Crédito]],0),31) | C15: ABONO EFECT | D15: INGRES. REQU | E15: VALOR CUOTA MAS SEGURO | G15: =+K19-H3 | H15: TASA NOMINAL ANUAL MES VENCIDO | K15: =+K14*12
A16: OPCION 1 | B16: 13.5 | C16: =ESTUDIO!I11 | D16: =ESTUDIO!I15 | H16: TASA EFECTIVA ANUAL | K16: =G6
A17: OPCION 2 | B17: 12 | C17: =ESTUDIO!L11 | D17: =ESTUDIO!L15 | E17: MES | F17: SALDO K | G17: ABONO CAPITAL | H17: VLR INTERESES | I17: VLR CUOTA SIN SEGURO | J17: SEGURO | K17: VLR CUOTA MAS SEGURO
A18: OPCION 3 | B18: 11 | C18: =ESTUDIO!O11 | D18: =ESTUDIO!O15 | E18: 0 | F18: =G7
A19: OPCION 4 | B19: 10 | C19: =ESTUDIO!I39 | D19: =ESTUDIO!I43 | E19: 1 | F19: =+IF(F18-G19<0,0,F18-G19) | G19: =I19-H19 | H19: =F18*$G$8 | I19: =IF(ROUND(F18,0)=0,0,PMT($G$8,$G$9,-$G$7)) | J19: =+IF(ROUND(F18,0)=0,0,+$G$13+$G$14) | K19: =+J19+I19
A20: OPCION 5 | B20: 9 | C20: =ESTUDIO!L39 | D20: =ESTUDIO!L43 | E20: 2 | F20: =+IF(F19-G20<0,0,F19-G20) | G20: =I20-H20 | H20: =F19*$G$8 | I20: =IF(ROUND(F19,0)=0,0,PMT($G$8,$G$9,-$G$7)) | J20: =+IF(ROUND(F19,0)=0,0,+$G$13+$G$14) | K20: =+J20+I20
A21: OPCION 6 | B21: 8.5 | C21: =ESTUDIO!O39 | D21: =ESTUDIO!O43 | E21: 3 | F21: =+IF(F20-G21<0,0,F20-G21) | G21: =I21-H21 | H21: =F20*$G$8 | I21: =IF(ROUND(F20,0)=0,0,PMT($G$8,$G$9,-$G$7)) | J21: =+IF(ROUND(F20,0)=0,0,+$G$13+$G$14) | K21: =+J21+I21
A22: COLSULTOR | B22: =INDEX(Tabla_BD[#All],MATCH(B2,Tabla_BD[[#All],['# Crédito]],0),13) | C22: EL VALOR DE INGRESOS DEBE SER EL RESULTADO INDICADO EN EL FORMATO DE PERFILAMIENTO (INGRESOS TOTALES) | E22: 4 | F22: =+IF(F21-G22<0,0,F21-G22) | G22: =I22-H22 | H22: =F21*$G$8 | I22: =IF(ROUND(F21,0)=0,0,PMT($G$8,$G$9,-$G$7)) | J22: =+IF(ROUND(F21,0)=0,0,+$G$13+$G$14) | K22: =+J22+I22
A23: ACTIVIDAD ECON | B23: =INDEX(Tabla_BD[#All],MATCH(B2,Tabla_BD[[#All],['# Crédito]],0),34) | E23: 5 | F23: =+IF(F22-G23<0,0,F22-G23) | G23: =I23-H23 | H23: =F22*$G$8 | I23: =IF(ROUND(F22,0)=0,0,PMT($G$8,$G$9,-$G$7)) | J23: =+IF(ROUND(F22,0)=0,0,+$G$13+$G$14) | K23: =+J23+I23
A24: DIFERNCIA | B24: =M7 | E24: 6 | F24: =+IF(F23-G24<0,0,F23-G24) | G24: =I24-H24 | H24: =F23*$G$8 | I24: =IF(ROUND(F23,0)=0,0,PMT($G$8,$G$9,-$G$7)) | J24: =+IF(ROUND(F23,0)=0,0,+$G$13+$G$14) | K24: =+J24+I24
A25: ABONO EFECTIVO | B25: =INDEX(Tabla_BD[#All],MATCH(B2,Tabla_BD[[#All],['# Crédito]],0),32) | E25: 7 | F25: =+IF(F24-G25<0,0,F24-G25) | G25: =I25-H25 | H25: =F24*$G$8 | I25: =IF(ROUND(F24,0)=0,0,PMT($G$8,$G$9,-$G$7)) | J25: =+IF(ROUND(F24,0)=0,0,+$G$13+$G$14) | K25: =+J25+I25
A26: INGRESOS | B26: =INDEX(Tabla_BD[#All],MATCH(B2,Tabla_BD[[#All],['# Crédito]],0),33) | E26: 8 | F26: =+IF(F25-G26<0,0,F25-G26) | G26: =I26-H26 | H26: =F25*$G$8 | I26: =IF(ROUND(F25,0)=0,0,PMT($G$8,$G$9,-$G$7)) | J26: =+IF(ROUND(F25,0)=0,0,+$G$13+$G$14) | K26: =+J26+I26
E27: 9 | F27: =+IF(F26-G27<0,0,F26-G27) | G27: =I27-H27 | H27: =F26*$G$8 | I27: =IF(ROUND(F26,0)=0,0,PMT($G$8,$G$9,-$G$7)) | J27: =+IF(ROUND(F26,0)=0,0,+$G$13+$G$14) | K27: =+J27+I27
E28: 10 | F28: =+IF(F27-G28<0,0,F27-G28) | G28: =I28-H28 | H28: =F27*$G$8 | I28: =IF(ROUND(F27,0)=0,0,PMT($G$8,$G$9,-$G$7)) | J28: =+IF(ROUND(F27,0)=0,0,+$G$13+$G$14) | K28: =+J28+I28
E29: 11 | F29: =+IF(F28-G29<0,0,F28-G29) | G29: =I29-H29 | H29: =F28*$G$8 | I29: =IF(ROUND(F28,0)=0,0,PMT($G$8,$G$9,-$G$7)) | J29: =+IF(ROUND(F28,0)=0,0,+$G$13+$G$14) | K29: =+J29+I29
E30: 12 | F30: =+IF(F29-G30<0,0,F29-G30) | G30: =I30-H30 | H30: =F29*$G$8 | I30: =IF(ROUND(F29,0)=0,0,PMT($G$8,$G$9,-$G$7)) | J30: =+IF(ROUND(F29,0)=0,0,+$G$13+$G$14) | K30: =+J30+I30
E31: 13 | F31: =+IF(F30-G31<0,0,F30-G31) | G31: =I31-H31 | H31: =F30*$G$8 | I31: =IF(ROUND(F30,0)=0,0,PMT($G$8,$G$9,-$G$7)) | J31: =+IF(ROUND(F30,0)=0,0,+$G$13+$G$14) | K31: =+J31+I31
A32: VIS DAVIVIENDA | E32: 14 | F32: =+IF(F31-G32<0,0,F31-G32) | G32: =I32-H32 | H32: =F31*$G$8 | I32: =IF(ROUND(F31,0)=0,0,PMT($G$8,$G$9,-$G$7)) | J32: =+IF(ROUND(F31,0)=0,0,+$G$13+$G$14) | K32: =+J32+I32
B33: BANCO DE BOGOTA | E33: 15 | F33: =+IF(F32-G33<0,0,F32-G33) | G33: =I33-H33 | H33: =F32*$G$8 | I33: =IF(ROUND(F32,0)=0,0,PMT($G$8,$G$9,-$G$7)) | J33: =+IF(ROUND(F32,0)=0,0,+$G$13+$G$14) | K33: =+J33+I33
E34: 16 | F34: =+IF(F33-G34<0,0,F33-G34) | G34: =I34-H34 | H34: =F33*$G$8 | I34: =IF(ROUND(F33,0)=0,0,PMT($G$8,$G$9,-$G$7)) | J34: =+IF(ROUND(F33,0)=0,0,+$G$13+$G$14) | K34: =+J34+I34
E35: 17 | F35: =+IF(F34-G35<0,0,F34-G35) | G35: =I35-H35 | H35: =F34*$G$8 | I35: =IF(ROUND(F34,0)=0,0,PMT($G$8,$G$9,-$G$7)) | J35: =+IF(ROUND(F34,0)=0,0,+$G$13+$G$14) | K35: =+J35+I35
E36: 18 | F36: =+IF(F35-G36<0,0,F35-G36) | G36: =I36-H36 | H36: =F35*$G$8 | I36: =IF(ROUND(F35,0)=0,0,PMT($G$8,$G$9,-$G$7)) | J36: =+IF(ROUND(F35,0)=0,0,+$G$13+$G$14) | K36: =+J36+I36
E37: 19 | F37: =+IF(F36-G37<0,0,F36-G37) | G37: =I37-H37 | H37: =F36*$G$8 | I37: =IF(ROUND(F36,0)=0,0,PMT($G$8,$G$9,-$G$7)) | J37: =+IF(ROUND(F36,0)=0,0,+$G$13+$G$14) | K37: =+J37+I37
E38: 20 | F38: =+IF(F37-G38<0,0,F37-G38) | G38: =I38-H38 | H38: =F37*$G$8 | I38: =IF(ROUND(F37,0)=0,0,PMT($G$8,$G$9,-$G$7)) | J38: =+IF(ROUND(F37,0)=0,0,+$G$13+$G$14) | K38: =+J38+I38
E39: 21 | F39: =+IF(F38-G39<0,0,F38-G39) | G39: =I39-H39 | H39: =F38*$G$8 | I39: =IF(ROUND(F38,0)=0,0,PMT($G$8,$G$9,-$G$7)) | J39: =+IF(ROUND(F38,0)=0,0,+$G$13+$G$14) | K39: =+J39+I39
E40: 22 | F40: =+IF(F39-G40<0,0,F39-G40) | G40: =I40-H40 | H40: =F39*$G$8 | I40: =IF(ROUND(F39,0)=0,0,PMT($G$8,$G$9,-$G$7)) | J40: =+IF(ROUND(F39,0)=0,0,+$G$13+$G$14) | K40: =+J40+I40
...

Sheet ESTUDIO
B1: LEY DE VIVIENDA 546 1999
E5: CONDICIONES ACTUALES BANCO | I5: PROYECCIONES DE AHORRO (SISTEMA DE AMORTIZACION EN PESOS) | T5: FRECH | U5: =B21*H21
E6: CAPITAL ADEUDADO | F6: =ACTUAL!G7 | I6: OPCIÓN #1 | L6: OPCIÓN #2 | O6: OPCIÓN #3
E7: AÑOS PENDIENTES | F7: =F8/12 | I7: =I8/12 | L7: =L8/12 | O7: =O8/12 | T7: VARIACION | U7: =ACTUAL!M7
B8: FECHA DE ESTUDIO | E8: MESES PENDIENTES | F8: =ACTUAL!G9 | I8: =ACTUAL!J7 | L8: =ACTUAL!J8 | O8: =ACTUAL!J9 | T8: APLICAR | U8: =U7+15000
B9: =ACTUAL!E1 | E9: CUOTA | F9: =ACTUAL!K1 | I9: ='PESOS (1)'!F19+H10-B21+U8 | L9: ='PESOS (2)'!F19+H10-B21+U8 | O9: ='PESOS (3)'!F19+H10-B21+U8
B10: CREDITO N° | E10: INTERESES.CAPITALSEGUROS | F10: =ACTUAL!K2 | G10: =ACTUAL!K3 | H10: =ACTUAL!G12 | I10: =F10 | J10: =G10+I11 | K10: =H10 | L10: =F10 | M10: =G10+L11 | N10: =H10 | O10: =F10 | P10: =G10+O11 | Q10: =H10
B11: =ACTUAL!B2 | E11: PARTICIPACION ADICIONAL A CAPITAL | I11: =I9-F9 | L11: =L9-F9 | O11: =O9-F9
B12: NOMBRE CLIENTE | E12: TOTAL A PAGAR | F12: =(F9*F8)+B21*(F8-H21) | I12: =SUM('PESOS (1)'!F19:F378)+(H10*I8)-U5+(I8*U8) | L12: =SUM('PESOS (2)'!F19:F378)+(H10*L8)-U5+(L8*U8) | O12: =SUM('PESOS (3)'!F19:F378)+(H10*O8)-U5+(O8*U8)
B13: =ACTUAL!B3 | E13: CAPITAL A PAGAR | F13: =F6 | I13: =F13 | L13: =F13 | O13: =F13
E14: INTERESES A PAGAR | F14: =F12-F13 | I14: =I12-I13 | L14: =L12-L13 | O14: =O12-O13
B15: =ACTUAL!B4 | E15: INGRESOS REQUERIDOS SEGÚN FORM. PERFILAMIENTO | I15: =IF(OR(ACTUAL!E4=BANCOS!D5, ACTUAL!E4=BANCOS!D6, ACTUAL!E4=BANCOS!D12), 0, ((I9+ACTUAL!B9) + IF(ISNUMBER(FIND("DAVIVIENDA", B15)), ACTUAL!B21, 0)) / ACTUAL!D13) | L15: =IF(OR(ACTUAL!E4=BANCOS!D5, ACTUAL!E4=BANCOS!D6, ACTUAL!E4=BANCOS!D12), 0, ((L9+ACTUAL!B9) + IF(ISNUMBER(FIND("DAVIVIENDA", B15)), ACTUAL!B21, 0)) / ACTUAL!D13) | O15: =IF(OR(ACTUAL!E4=BANCOS!D5, ACTUAL!E4=BANCOS!D6, ACTUAL!E4=BANCOS!D12), 0, ((O9+ACTUAL!B9) + IF(ISNUMBER(FIND("DAVIVIENDA", B15)), ACTUAL!B21, 0)) / ACTUAL!D13)
B16: DINERO PAGADO | E16: BENEFICIOS OBTENIDOS: | I16: TIEMPO Y DINERO AHORRADO
B17: =ACTUAL!H2 | E17: AÑOS REDUCIDOS | I17: =I18/12 | L17: =L18/12 | O17: =O18/12
B18: TASA ACTUAL | E18: CUOTAS REDUCIDAS | I18: =F8-I8 | L18: =F8-L8 | O18: =F8-O8
B19: PESOS | C19: =ACTUAL!B8 | E19: DINERO AHORRADO EN INTERESES | I19: =F14-I14 | K19: =((I19*1)/F14) | L19: =F14-L14 | N19: =((L19*1)/F14) | O19: =F14-O14 | Q19: =O19*1/F14
B21: =ACTUAL!B9 | E21: CUOTAS RESTANTES DEL FRECH (SI APLI) | F21: 84 | G21: =ACTUAL!J5 | H21: =F21-G21 | I21: HONORARIOS 6% O TARIFA MINIMA ($1,800,000 APLICA PARA AHORRO INFERIOR A $30.000.000) IVA INCLUIDO
B22: SUBSIDIO FRECH | E22: HONORARIOS | I22: =IF(I19<30000000,1800000,I19*0.06) | L22: =IF(L19<30000000,1800000,L19*0.06) | O22: =IF(O19<30000000,1800000,O19*0.06)
B24: CONSULTOR FINANCIERO | E24: DOCUMENTACIÓN NECESARIA PARA INICIAR TU PROCESO DE REDUCCIÓN DE CREDITO: | I24: 1. Acuerdo de servicios.
I25: 2. Autorización para autenticar.
B26: =ACTUAL!B22 | I26: 3. Copia de cedula al 150% de titulares.
I27: 4. Certificaciones de ingreso según la entidad financiera. (no es necesario para Bancolombia, Caja Social y La Hipotecaria).
B29: LEY DE VIVIENDA 546 1999
E33: CONDICIONES ACTUALES BANCO | I33: =I5 | T33: FRECH | U33: =U5
E34: CAPITAL ADEUDADO | F34: =F6 | I34: OPCIÓN #4 | L34: OPCIÓN #5 | O34: OPCIÓN #6
E35: AÑOS PENDIENTES | F35: =F7 | I35: =ACTUAL!B19 | L35: =ACTUAL!B20 | O35: =ACTUAL!B21 | T35: VARIACION | U35: =U7
B36: FECHA DE ESTUDIO | E36: MESES PENDIENTES | F36: =F8 | I36: =ACTUAL!J10 | L36: =ACTUAL!J11 | O36: =ACTUAL!J12 | T36: APLICAR | U36: =U8
B37: =B9 | E37: CUOTA | F37: =F9 | I37: ='PESOS (4)'!F19+H38-B49+U36 | L37: ='PESOS (5)'!F19+H38-B49+U36 | O37: ='PESOS (6)'!F19+H38-B49+U36
B38: CREDITO N° | E38: INTERESES.CAPITALSEGUROS | F38: =F10 | G38: =G10 | H38: =H10 | I38: =F38 | J38: =G38+I39 | K38: =H38 | L38: =F38 | M38: =G38+L39 | N38: =H38 | O38: =F38 | P38: =G38+O39 | Q38: =H38
B39: =B11 | E39: PARTICIPACION ADICIONAL A CAPITAL | I39: =I37-F37 | L39: =L37-F37 | O39: =O37-F37
B40: NOMBRE CLIENTE | E40: TOTAL A PAGAR | F40: =F12 | I40: =SUM('PESOS (4)'!F19:F378)+(H38*I36)-U33+(I36*U36) | L40: =SUM('PESOS (5)'!F19:F378)+(H38*L36)-U33+(L36*U36) | O40: =SUM('PESOS (6)'!F19:F378)+(H38*O36)-U33+(O36*U36)
B41: =B13 | E41: CAPITAL A PAGAR | F41: =F13 | I41: =F41 | L41: =F41 | O41: =F41
E42: INTERESES A PAGAR | F42: =F14 | I42: =I40-I41 | L42: =L40-L41 | O42: =O40-O41
B43: =B15 | E43: INGRESOS REQUERIDOS SEGÚN FORM. PERFILAMIENTO | I43: =IF(OR(ACTUAL!E4=BANCOS!D5, ACTUAL!E4=BANCOS!D6, ACTUAL!E4=BANCOS!D12), 0, ((I37+ACTUAL!B9) + IF(ISNUMBER(FIND("DAVIVIENDA", B15)), ACTUAL!B21, 0)) / ACTUAL!D13) | L43: =IF(OR(ACTUAL!E4=BANCOS!D5, ACTUAL!E4=BANCOS!D6, ACTUAL!E4=BANCOS!D12), 0, ((L37+ACTUAL!B9) + IF(ISNUMBER(FIND("DAVIVIENDA", B15)), ACTUAL!B21, 0)) / ACTUAL!D13) | O43: =IF(OR(ACTUAL!E4=BANCOS!D5, ACTUAL!E4=BANCOS!D6, ACTUAL!E4=BANCOS!D12), 0, ((O37+ACTUAL!B9) + IF(ISNUMBER(FIND("DAVIVIENDA", B15)), ACTUAL!B21, 0)) / ACTUAL!D13)
B44: DINERO PAGADO | E44: BENEFICIOS OBTENIDOS: | I44: TIEMPO Y DINERO AHORRADO
B45: =B17 | E45: AÑOS REDUCIDOS | I45: =I46/12 | L45: =L46/12 | O45: =O46/12
B46: TASA ACTUAL | E46: CUOTAS REDUCIDAS | I46: =F36-I36 | L46: =F36-L36 | O46: =F36-O36
B47: PESOS | C47: =C19 | E47: DINERO AHORRADO EN INTERESES | I47: =F42-I42 | K47: =((I47*1)/F42) | L47: =F42-L42 | N47: =((L47*1)/F42) | O47: =F42-O42 | Q47: =O47*1/F42
B49: =B21 | E49: CUOTAS RESTANTES DEL FRECH (SI APLI) | F49: =F21 | G49: =G21 | H49: =H21 | I49: =I21
B50: SUBSIDIO FRECH | E50: HONORARIOS | I50: =IF(I47<30000000,1800000,I47*0.06) | L50: =IF(L47<30000000,1800000,L47*0.06) | O50: =IF(O47<30000000,1800000,O47*0.06)
...

Sheet SIN
F2: APLIQUE LOS BENEFICIOS DE LA LEY DE VIVIENDA COMO LO HAN HECHO MILES DE FAMILIAS COLOMBIANAS CON NUESTRA ASESORIA
B3: REDUCCIÓN DE CREDITO HIPOTECARIO | E3: ESTUDIO FINANCIERO PROYECCIONES DE AHORRO CON REDUCCION DE SEGUROS INCLUIDA
E4: CONDICIONES ACTUALES BANCO | I4: SISTEMA DE AMORTIZACION EN PESOS | T4: FRECH | U4: =B20*H20
E5: CAPITAL ADEUDADO | F5: =ACTUAL!G7 | I5: OPC 1 "NUEVO PLAZO" | L5: OPC 2 "NUEVO PLAZO" | O5: OPC 3 "NUEVO PLAZO"
E6: AÑOS PENDIENTES | F6: =F7/12 | I6: =I7/12 | L6: =L7/12 | O6: =O7/12 | T6: VARIACION | U6: =ACTUAL!M7
B7: FECHA DE ESTUDIO | E7: MESES PENDIENTES | F7: =ACTUAL!G9 | I7: =ACTUAL!J7 | L7: =ACTUAL!J8 | O7: =ACTUAL!J9 | T7: APLICAR | U7: =IF(U6<0,0,U6)
B8: =ACTUAL!E1 | E8: CUOTA Y DISTRIBUCION CUOTA | F8: =ACTUAL!K1 | I8: ='PESOS (1)'!F19-B20+U7 | L8: ='PESOS (2)'!F19-B20+U7 | O8: ='PESOS (3)'!F19-B20+U7
B9: CIUDAD | F9: =ESTUDIO!F10 | G9: =ESTUDIO!G10 | H9: =ESTUDIO!H10 | I9: =F9 | J9: =G9+I10+H9 | K9: 0 | L9: =F9 | M9: =G9+L10+H9 | N9: 0 | O9: =F9 | P9: =G9+O10+H9 | Q9: 0
B10: =ACTUAL!E2 | E10: MEJORA A CAPITAL EN CADA OPCIÓN | I10: =I8-F8 | L10: =L8-F8 | O10: =O8-F8
B11: NOMBRE CLIENTE | E11: TOTAL POR PAGAR | F11: =SUM(ACTUAL!I19:I378)+(H9*F7)-U4+(F7*U7) | I11: =SUM('PESOS (1)'!F19:F378)+((H9/2)*I7)-U4+(L7*U7) | L11: =SUM('PESOS (2)'!F19:F378)+((H9/2)*I7)-U4+(L7*U7) | O11: =SUM('PESOS (3)'!F19:F378)+((H9/2)*I7)-U4+(L7*U7)
B12: =ACTUAL!E3 | E12: CAPITAL POR PAGAR | F12: =F5 | I12: =F12 | L12: =F12 | O12: =F12
B13: ENTIDAD FINANCIERA | E13: INTERESES A PAGAR EN CADA OPCION | F13: =F11-F12 | I13: =I11-I12 | L13: =L11-L12 | O13: =O11-O12
B14: =ACTUAL!E4 | F14: INGRESOS REQUERIDOS | I14: =(I8+B20+H9)/(0.28) | L14: =(L8+B20+H9)/(0.28) | O14: =(O8+B20+H9)/(0.28)
B15: =ACTUAL!G2 | E15: BENEFICIOS OBTENIDOS: | I15: TIEMPO Y DINERO AHORRADO
B16: =ACTUAL!H2 | E16: AÑOS REDUCIDOS | I16: =I17/12 | L16: =L17/12 | O16: =O17/12
B17: TASA ACTUAL | E17: CUOTAS REDUCIDAS | I17: =F7-I7 | L17: =F7-L7 | O17: =F7-O7
B18: =ACTUAL!H1 | C18: =ACTUAL!K16 | E18: DINERO AHORRADO EN INTERESES | I18: =F13-I13 | K18: =((I18*1)/F13) | L18: =F13-L13 | N18: =((L18*1)/F13) | O18: =F13-O13 | Q18: =O18*1/F13
B19: VALOR BENEFICIO
B20: =ACTUAL!H3 | E20: CUOTAS RESTANTES DEL FRECH (SI APLI) | F20: 84 | G20: =ACTUAL!J5 | H20: =F20-G20 | I20: HONORARIOS 6% O TARIFA MINIMA ($1,200,000) PAGADO CONTRA EXITO DE LA OPERACIÓN
B21: LEY DE VIVIENDA 546 | E21: HONORARIOS NORMALES | I21: =IF(I18<20000000,1200000,I18*0.06) | L21: =IF(L18<20000000,1200000,L18*0.06) | O21: =IF(O18<20000000,1200000,O18*0.06)
F24: APLIQUE LOS BENEFICIOS DE LA LEY DE VIVIENDA COMO LO HAN HECHO MILES DE FAMILIAS COLOMBIANAS CON NUESTRA ASESORIA
B25: REDUCCIÓN DE CREDITO HIPOTECARIO | E25: ESTUDIO FINANCIERO PROYECCIONES DE AHORRO CON REDUCCION DE SEGUROS INCLUIDA
E26: CONDICIONES ACTUALES BANCO | I26: SISTEMA DE AMORTIZACION EN PESOS
E27: CAPITAL ADEUDADO | F27: =F5 | I27: OPC 4 "NUEVO PLAZO" | L27: OPC 5 "NUEVO PLAZO" | O27: OPC 6 "NUEVO PLAZO"
E28: AÑOS PENDIENTES | F28: =F29/12 | I28: =I29/12 | L28: =L29/12 | O28: =O29/12
B29: FECHA DE ESTUDIO | E29: MESES PENDIENTES | F29: =F7 | I29: =ACTUAL!J10 | L29: =ACTUAL!J11 | O29: =ACTUAL!J12
B30: =B8 | E30: CUOTA Y DISTRIBUCION CUOTA | F30: =F8 | I30: ='PESOS (4)'!F19-B20+U7 | L30: ='PESOS (5)'!F19-B20+U7 | O30: ='PESOS (6)'!F19-B20+U7
B31: CIUDAD | F31: =F9 | G31: =G9 | H31: =H9 | I31: =F31 | J31: =G31+I32 | K31: 0 | L31: =F31 | M31: =G31+L32 | N31: 0 | O31: =F31 | P31: =G31+O32 | Q31: 0
B32: =B10 | E32: MEJORA A CAPITAL EN CADA OPCIÓN | I32: =I30-F30 | L32: =L30-F30 | O32: =O30-F30
B33: NOMBRE CLIENTE | E33: TOTAL POR PAGAR | F33: =F11 | I33: =SUM('PESOS (4)'!F19:F278)+(H31*L29/2)-U4+(L29*U7) | L33: =SUM('PESOS (5)'!F19:F278)+(H31*L29/2)-U4+(L29*U7) | O33: =SUM('PESOS (6)'!F19:F278)+(H31*O29/2)-U4+(O29*U7)
B34: =B12 | E34: CAPITAL POR PAGAR | F34: =F27 | I34: =F34 | L34: =F34 | O34: =F34
B35: ENTIDAD FINANCIERA | E35: INTERESES A PAGAR EN CADA OPCION | F35: =F33-F34 | I35: =I33-I34 | L35: =L33-L34 | O35: =O33-O34
B36: =B14 | F36: INGRESOS REQUERIDOS | I36: =(I30+B42+H9)/(0.28) | L36: =(L30+B42+H9)/(0.28) | O36: =(O30+B42+H9)/(0.28)
B37: =ACTUAL!G2 | E37: BENEFICIOS OBTENIDOS: | I37: TIEMPO Y DINERO AHORRADO
B38: =B16 | E38: AÑOS REDUCIDOS | I38: =I39/12 | L38: =L39/12 | O38: =O39/12
B39: TASA ACTUAL | E39: CUOTAS REDUCIDAS | I39: =F29-I29 | L39: =F29-L29 | O39: =F29-O29
B40: =B18 | C40: =C18 | E40: DINERO AHORRADO EN INTERESES | I40: =F35-I35 | K40: =((I40*1)/F35) | L40: =F35-L35 | N40: =((L40*1)/F35) | O40: =F35-O35 | Q40: =O40*1/F35
B41: VALOR BENEFICIO
B42: =B20 | E42: CUOTAS RESTANTES DEL FRECH (SI APLI) | F42: 84 | G42: =G20 | H42: =F42-G42 | I42: =I20
B43: LEY DE VIVIENDA 546 | E43: HONORARIOS NORMALES | I43: =IF(I40<20000000,1200000,I40*0.06) | L43: =IF(L40<20000000,1200000,L40*0.06) | O43: =IF(O40<20000000,1200000,O40*0.06)

Sheet PESOS  (1)
B7: VALOR PRESTAMO | D7: =ACTUAL!G7 | E7: OPCIÓN 1
B8: TASA DE INTERES MES | D8: =H14
B9: PLAZO DEL CREDITO (MESES) | D9: =ACTUAL!J7
B10: Edad Cliente | D10: 0
B11: Valor Inmueble | D11: 0
B12: Total seguros | D12: 0
B13: Seguro de Vida | D13: =ACTUAL!G13
B14: Incendio y Terremoto sin iva | D14: =ACTUAL!G14 | E14: TASA NOMINAL MV | H14: =+(1+H16)^(0.0833333333333333)-1
B15: VALOR CUOTA MAS SEGURO | D15: =+H19 | E15: TASA NOMINAL ANUAL MES VENCIDO | H15: =+H14*12
E16: TASA EFECTIVA ANUAL | H16: =ACTUAL!K16
B17: MES | C17: SALDO K | D17: ABONO CAPITAL | E17: VLR INTERESES | F17: VLR CUOTA SIN SEGURO | G17: SEGURO | H17: VLR CUOTA MAS SEGURO
B18: 0 | C18: =D7
B19: 1 | C19: =+IF(C18-D19<0,0,C18-D19) | D19: =F19-E19 | E19: =C18*$D$8 | F19: =IF(ROUND(C18,0)=0,0,PMT($D$8,$D$9,-$D$7)) | G19: =+IF(ROUND(C18,0)=0,0,+$D$13+$D$14) | H19: =+G19+F19
B20: 2 | C20: =+IF(C19-D20<0,0,C19-D20) | D20: =F20-E20 | E20: =C19*$D$8 | F20: =IF(ROUND(C19,0)=0,0,PMT($D$8,$D$9,-$D$7)) | G20: =+IF(ROUND(C19,0)=0,0,+$D$13+$D$14) | H20: =+G20+F20
B21: 3 | C21: =+IF(C20-D21<0,0,C20-D21) | D21: =F21-E21 | E21: =C20*$D$8 | F21: =IF(ROUND(C20,0)=0,0,PMT($D$8,$D$9,-$D$7)) | G21: =+IF(ROUND(C20,0)=0,0,+$D$13+$D$14) | H21: =+G21+F21
B22: 4 | C22: =+IF(C21-D22<0,0,C21-D22) | D22: =F22-E22 | E22: =C21*$D$8 | F22: =IF(ROUND(C21,0)=0,0,PMT($D$8,$D$9,-$D$7)) | G22: =+IF(ROUND(C21,0)=0,0,+$D$13+$D$14) | H22: =+G22+F22
B23: 5 | C23: =+IF(C22-D23<0,0,C22-D23) | D23: =F23-E23 | E23: =C22*$D$8 | F23: =IF(ROUND(C22,0)=0,0,PMT($D$8,$D$9,-$D$7)) | G23: =+IF(ROUND(C22,0)=0,0,+$D$13+$D$14) | H23: =+G23+F23
B24: 6 | C24: =+IF(C23-D24<0,0,C23-D24) | D24: =F24-E24 | E24: =C23*$D$8 | F24: =IF(ROUND(C23,0)=0,0,PMT($D$8,$D$9,-$D$7)) | G24: =+IF(ROUND(C23,0)=0,0,+$D$13+$D$14) | H24: =+G24+F24
B25: 7 | C25: =+IF(C24-D25<0,0,C24-D25) | D25: =F25-E25 | E25: =C24*$D$8 | F25: =IF(ROUND(C24,0)=0,0,PMT($D$8,$D$9,-$D$7)) | G25: =+IF(ROUND(C24,0)=0,0,+$D$13+$D$14) | H25: =+G25+F25
B26: 8 | C26: =+IF(C25-D26<0,0,C25-D26) | D26: =F26-E26 | E26: =C25*$D$8 | F26: =IF(ROUND(C25,0)=0,0,PMT($D$8,$D$9,-$D$7)) | G26: =+IF(ROUND(C25,0)=0,0,+$D$13+$D$14) | H26: =+G26+F26
B27: 9 | C27: =+IF(C26-D27<0,0,C26-D27) | D27: =F27-E27 | E27: =C26*$D$8 | F27: =IF(ROUND(C26,0)=0,0,PMT($D$8,$D$9,-$D$7)) | G27: =+IF(ROUND(C26,0)=0,0,+$D$13+$D$14) | H27: =+G27+F27
B28: 10 | C28: =+IF(C27-D28<0,0,C27-D28) | D28: =F28-E28 | E28: =C27*$D$8 | F28: =IF(ROUND(C27,0)=0,0,PMT($D$8,$D$9,-$D$7)) | G28: =+IF(ROUND(C27,0)=0,0,+$D$13+$D$14) | H28: =+G28+F28
B29: 11 | C29: =+IF(C28-D29<0,0,C28-D29) | D29: =F29-E29 | E29: =C28*$D$8 | F29: =IF(ROUND(C28,0)=0,0,PMT($D$8,$D$9,-$D$7)) | G29: =+IF(ROUND(C28,0)=0,0,+$D$13+$D$14) | H29: =+G29+F29
B30: 12 | C30: =+IF(C29-D30<0,0,C29-D30) | D30: =F30-E30 | E30: =C29*$D$8 | F30: =IF(ROUND(C29,0)=0,0,PMT($D$8,$D$9,-$D$7)) | G30: =+IF(ROUND(C29,0)=0,0,+$D$13+$D$14) | H30: =+G30+F30
... B198: 180 | C198: =+IF(C197-D198<0,0,C197-D198) | D198: =F198-E198 | E198: =C197*$D$8 | F198: =IF(ROUND(C197,0)=0,0,PMT($D$8,$D$9,-$D$7)) | G198: =+IF(ROUND(C197,0)=0,0,+$D$13+$D$14) | H198: =+G198+F198
B199: =+B198+1 | C199: =+IF(C198-D199<0,0,C198-D199) | D199: =F199-E199 | E199: =C198*$D$8 | F199: =IF(ROUND(C198,0)=0,0,PMT($D$8,$D$9,-$D$7)) | G199: =+IF(ROUND(C198,0)=0,0,+$D$13+$D$14) | H199: =+G199+F199
B200: =+B199+1 | C200: =+IF(C199-D200<0,0,C199-D200) | D200: =F200-E200 | E200: =C199*$D$8 | F200: =IF(ROUND(C199,0)=0,0,PMT($D$8,$D$9,-$D$7)) | G200: =+IF(ROUND(C199,0)=0,0,+$D$13+$D$14) | H200: =+G200+F200
B201: =+B200+1 | C201: =+IF(C200-D201<0,0,C200-D201) | D201: =F201-E201 | E201: =C200*$D$8 | F201: =IF(ROUND(C200,0)=0,0,PMT($D$8,$D$9,-$D$7)) | G201: =+IF(ROUND(C200,0)=0,0,+$D$13+$D$14) | H201: =+G201+F201
B202: =+B201+1 | C202: =+IF(C201-D202<0,0,C201-D202) | D202: =F202-E202 | E202: =C201*$D$8 | F202: =IF(ROUND(C201,0)=0,0,PMT($D$8,$D$9,-$D$7)) | G202: =+IF(ROUND(C201,0)=0,0,+$D$13+$D$14) | H202: =+G202+F202
B203: =+B202+1 | C203: =+IF(C202-D203<0,0,C202-D203) | D203: =F203-E203 | E203: =C202*$D$8 | F203: =IF(ROUND(C202,0)=0,0,PMT($D$8,$D$9,-$D$7)) | G203: =+IF(ROUND(C202,0)=0,0,+$D$13+$D$14) | H203: =+G203+F203
B204: =+B203+1 | C204: =+IF(C203-D204<0,0,C203-D204) | D204: =F204-E204 | E204: =C203*$D$8 | F204: =IF(ROUND(C203,0)=0,0,PMT($D$8,$D$9,-$D$7)) | G204: =+IF(ROUND(C203,0)=0,0,+$D$13+$D$14) | H204: =+G204+F204
B205: =+B204+1 | C205: =+IF(C204-D205<0,0,C204-D205) | D205: =F205-E205 | E205: =C204*$D$8 | F205: =IF(ROUND(C204,0)=0,0,PMT($D$8,$D$9,-$D$7)) | G205: =+IF(ROUND(C204,0)=0,0,+$D$13+$D$14) | H205: =+G205+F205
B206: =+B205+1 | C206: =+IF(C205-D206<0,0,C205-D206) | D206: =F206-E206 | E206: =C205*$D$8 | F206: =IF(ROUND(C205,0)=0,0,PMT($D$8,$D$9,-$D$7)) | G206: =+IF(ROUND(C205,0)=0,0,+$D$13+$D$14) | H206: =+G206+F206
B207: =+B206+1 | C207: =+IF(C206-D207<0,0,C206-D207) | D207: =F207-E207 | E207: =C206*$D$8 | F207: =IF(ROUND(C206,0)=0,0,PMT($D$8,$D$9,-$D$7)) | G207: =+IF(ROUND(C206,0)=0,0,+$D$13+$D$14) | H207: =+G207+F207
B208: =+B207+1 | C208: =+IF(C207-D208<0,0,C207-D208) | D208: =F208-E208 | E208: =C207*$D$8 | F208: =IF(ROUND(C207,0)=0,0,PMT($D$8,$D$9,-$D$7)) | G208: =+IF(ROUND(C207,0)=0,0,+$D$13+$D$14) | H208: =+G208+F208
B209: =+B208+1 | C209: =+IF(C208-D209<0,0,C208-D209) | D209: =F209-E209 | E209: =C208*$D$8 | F209: =IF(ROUND(C208,0)=0,0,PMT($D$8,$D$9,-$D$7)) | G209: =+IF(ROUND(C208,0)=0,0,+$D$13+$D$14) | H209: =+G209+F209
B210: =+B209+1 | C210: =+IF(C209-D210<0,0,C209-D210) | D210: =F210-E210 | E210: =C209*$D$8 | F210: =IF(ROUND(C209,0)=0,0,PMT($D$8,$D$9,-$D$7)) | G210: =+IF(ROUND(C209,0)=0,0,+$D$13+$D$14) | H210: =+G210+F210
... B378: =+B377+1 | C378: =+IF(C377-D378<0,0,C377-D378) | D378: =F378-E378 | E378: =C377*$D$8 | F378: =IF(ROUND(C377,0)=0,0,PMT($D$8,$D$9,-$D$7)) | G378: =+IF(ROUND(C377,0)=0,0,+$D$13+$D$14) | H378: =+G378+F378

Sheet PESOS  (2)
B7: VALOR PRESTAMO | D7: =ACTUAL!G7 | E7: OPCIÓN 2
B8: TASA DE INTERES MES | D8: =H14
B9: PLAZO DEL CREDITO (MESES) | D9: =ACTUAL!J8
B10: Edad Cliente | D10: 0
B11: Valor Inmueble | D11: 0
B12: Total seguros | D12: 0
B13: Seguro de Vida | D13: =ACTUAL!G13
B14: Incendio y Terremoto sin iva | D14: =ACTUAL!G14 | E14: TASA NOMINAL MV | H14: =+(1+H16)^(0.0833333333333333)-1
B15: VALOR CUOTA MAS SEGURO | D15: =+H19 | E15: TASA NOMINAL ANUAL MES VENCIDO | H15: =+H14*12
E16: TASA EFECTIVA ANUAL | H16: =ACTUAL!K16
B17: MES | C17: SALDO K | D17: ABONO CAPITAL | E17: VLR INTERESES | F17: VLR CUOTA SIN SEGURO | G17: SEGURO | H17: VLR CUOTA MAS SEGURO
B18: 0 | C18: =D7
B19: 1 | C19: =+IF(C18-D19<0,0,C18-D19) | D19: =F19-E19 | E19: =C18*$D$8 | F19: =IF(ROUND(C18,0)=0,0,PMT($D$8,$D$9,-$D$7)) | G19: =+IF(ROUND(C18,0)=0,0,+$D$13+$D$14) | H19: =+G19+F19
B20: 2 | C20: =+IF(C19-D20<0,0,C19-D20) | D20: =F20-E20 | E20: =C19*$D$8 | F20: =IF(ROUND(C19,0)=0,0,PMT($D$8,$D$9,-$D$7)) | G20: =+IF(ROUND(C19,0)=0,0,+$D$13+$D$14) | H20: =+G20+F20
B21: 3 | C21: =+IF(C20-D21<0,0,C20-D21) | D21: =F21-E21 | E21: =C20*$D$8 | F21: =IF(ROUND(C20,0)=0,0,PMT($D$8,$D$9,-$D$7)) | G21: =+IF(ROUND(C20,0)=0,0,+$D$13+$D$14) | H21: =+G21+F21
B22: 4 | C22: =+IF(C21-D22<0,0,C21-D22) | D22: =F22-E22 | E22: =C21*$D$8 | F22: =IF(ROUND(C21,0)=0,0,PMT($D$8,$D$9,-$D$7)) | G22: =+IF(ROUND(C21,0)=0,0,+$D$13+$D$14) | H22: =+G22+F22
B23: 5 | C23: =+IF(C22-D23<0,0,C22-D23) | D23: =F23-E23 | E23: =C22*$D$8 | F23: =IF(ROUND(C22,0)=0,0,PMT($D$8,$D$9,-$D$7)) | G23: =+IF(ROUND(C22,0)=0,0,+$D$13+$D$14) | H23: =+G23+F23
B24: 6 | C24: =+IF(C23-D24<0,0,C23-D24) | D24: =F24-E24 | E24: =C23*$D$8 | F24: =IF(ROUND(C23,0)=0,0,PMT($D$8,$D$9,-$D$7)) | G24: =+IF(ROUND(C23,0)=0,0,+$D$13+$D$14) | H24: =+G24+F24
B25: 7 | C25: =+IF(C24-D25<0,0,C24-D25) | D25: =F25-E25 | E25: =C24*$D$8 | F25: =IF(ROUND(C24,0)=0,0,PMT($D$8,$D$9,-$D$7)) | G25: =+IF(ROUND(C24,0)=0,0,+$D$13+$D$14) | H25: =+G25+F25
B26: 8 | C26: =+IF(C25-D26<0,0,C25-D26) | D26: =F26-E26 | E26: =C25*$D$8 | F26: =IF(ROUND(C25,0)=0,0,PMT($D$8,$D$9,-$D$7)) | G26: =+IF(ROUND(C25,0)=0,0,+$D$13+$D$14) | H26: =+G26+F26
B27: 9 | C27: =+IF(C26-D27<0,0,C26-D27) | D27: =F27-E27 | E27: =C26*$D$8 | F27: =IF(ROUND(C26,0)=0,0,PMT($D$8,$D$9,-$D$7)) | G27: =+IF(ROUND(C26,0)=0,0,+$D$13+$D$14) | H27: =+G27+F27
B28: 10 | C28: =+IF(C27-D28<0,0,C27-D28) | D28: =F28-E28 | E28: =C27*$D$8 | F28: =IF(ROUND(C27,0)=0,0,PMT($D$8,$D$9,-$D$7)) | G28: =+IF(ROUND(C27,0)=0,0,+$D$13+$D$14) | H28: =+G28+F28
B29: 11 | C29: =+IF(C28-D29<0,0,C28-D29) | D29: =F29-E29 | E29: =C28*$D$8 | F29: =IF(ROUND(C28,0)=0,0,PMT($D$8,$D$9,-$D$7)) | G29: =+IF(ROUND(C28,0)=0,0,+$D$13+$D$14) | H29: =+G29+F29
B30: 12 | C30: =+IF(C29-D30<0,0,C29-D30) | D30: =F30-E30 | E30: =C29*$D$8 | F30: =IF(ROUND(C29,0)=0,0,PMT($D$8,$D$9,-$D$7)) | G30: =+IF(ROUND(C29,0)=0,0,+$D$13+$D$14) | H30: =+G30+F30
... B198: 180 | C198: =+IF(C197-D198<0,0,C197-D198) | D198: =F198-E198 | E198: =C197*$D$8 | F198: =IF(ROUND(C197,0)=0,0,PMT($D$8,$D$9,-$D$7)) | G198: =+IF(ROUND(C197,0)=0,0,+$D$13+$D$14) | H198: =+G198+F198
B199: =+B198+1 | C199: =+IF(C198-D199<0,0,C198-D199) | D199: =F199-E199 | E199: =C198*$D$8 | F199: =IF(ROUND(C198,0)=0,0,PMT($D$8,$D$9,-$D$7)) | G199: =+IF(ROUND(C198,0)=0,0,+$D$13+$D$14) | H199: =+G199+F199
B200: =+B199+1 | C200: =+IF(C199-D200<0,0,C199-D200) | D200: =F200-E200 | E200: =C199*$D$8 | F200: =IF(ROUND(C199,0)=0,0,PMT($D$8,$D$9,-$D$7)) | G200: =+IF(ROUND(C199,0)=0,0,+$D$13+$D$14) | H200: =+G200+F200
B201: =+B200+1 | C201: =+IF(C200-D201<0,0,C200-D201) | D201: =F201-E201 | E201: =C200*$D$8 | F201: =IF(ROUND(C200,0)=0,0,PMT($D$8,$D$9,-$D$7)) | G201: =+IF(ROUND(C200,0)=0,0,+$D$13+$D$14) | H201: =+G201+F201
B202: =+B201+1 | C202: =+IF(C201-D202<0,0,C201-D202) | D202: =F202-E202 | E202: =C201*$D$8 | F202: =IF(ROUND(C201,0)=0,0,PMT($D$8,$D$9,-$D$7)) | G202: =+IF(ROUND(C201,0)=0,0,+$D$13+$D$14) | H202: =+G202+F202
B203: =+B202+1 | C203: =+IF(C202-D203<0,0,C202-D203) | D203: =F203-E203 | E203: =C202*$D$8 | F203: =IF(ROUND(C202,0)=0,0,PMT($D$8,$D$9,-$D$7)) | G203: =+IF(ROUND(C202,0)=0,0,+$D$13+$D$14) | H203: =+G203+F203
B204: =+B203+1 | C204: =+IF(C203-D204<0,0,C203-D204) | D204: =F204-E204 | E204: =C203*$D$8 | F204: =IF(ROUND(C203,0)=0,0,PMT($D$8,$D$9,-$D$7)) | G204: =+IF(ROUND(C203,0)=0,0,+$D$13+$D$14) | H204: =+G204+F204
B205: =+B204+1 | C205: =+IF(C204-D205<0,0,C204-D205) | D205: =F205-E205 | E205: =C204*$D$8 | F205: =IF(ROUND(C204,0)=0,0,PMT($D$8,$D$9,-$D$7)) | G205: =+IF(ROUND(C204,0)=0,0,+$D$13+$D$14) | H205: =+G205+F205
B206: =+B205+1 | C206: =+IF(C205-D206<0,0,C205-D206) | D206: =F206-E206 | E206: =C205*$D$8 | F206: =IF(ROUND(C205,0)=0,0,PMT($D$8,$D$9,-$D$7)) | G206: =+IF(ROUND(C205,0)=0,0,+$D$13+$D$14) | H206: =+G206+F206
B207: =+B206+1 | C207: =+IF(C206-D207<0,0,C206-D207) | D207: =F207-E207 | E207: =C206*$D$8 | F207: =IF(ROUND(C206,0)=0,0,PMT($D$8,$D$9,-$D$7)) | G207: =+IF(ROUND(C206,0)=0,0,+$D$13+$D$14) | H207: =+G207+F207
B208: =+B207+1 | C208: =+IF(C207-D208<0,0,C207-D208) | D208: =F208-E208 | E208: =C207*$D$8 | F208: =IF(ROUND(C207,0)=0,0,PMT($D$8,$D$9,-$D$7)) | G208: =+IF(ROUND(C207,0)=0,0,+$D$13+$D$14) | H208: =+G208+F208
B209: =+B208+1 | C209: =+IF(C208-D209<0,0,C208-D209) | D209: =F209-E209 | E209: =C208*$D$8 | F209: =IF(ROUND(C208,0)=0,0,PMT($D$8,$D$9,-$D$7)) | G209: =+IF(ROUND(C208,0)=0,0,+$D$13+$D$14) | H209: =+G209+F209
B210: =+B209+1 | C210: =+IF(C209-D210<0,0,C209-D210) | D210: =F210-E210 | E210: =C209*$D$8 | F210: =IF(ROUND(C209,0)=0,0,PMT($D$8,$D$9,-$D$7)) | G210: =+IF(ROUND(C209,0)=0,0,+$D$13+$D$14) | H210: =+G210+F210
... B378: =+B377+1 | C378: =+IF(C377-D378<0,0,C377-D378) | D378: =F378-E378 | E378: =C377*$D$8 | F378: =IF(ROUND(C377,0)=0,0,PMT($D$8,$D$9,-$D$7)) | G378: =+IF(ROUND(C377,0)=0,0,+$D$13+$D$14) | H378: =+G378+F378

Sheet PESOS  (3)
B7: VALOR PRESTAMO | D7: =ACTUAL!G7 | E7: OPCIÓN 3
B8: TASA DE INTERES MES | D8: =H14
B9: PLAZO DEL CREDITO (MESES) | D9: =ACTUAL!J9
B10: Edad Cliente | D10: 0
B11: Valor Inmueble | D11: 0
B12: Total seguros | D12: 0
B13: Seguro de Vida | D13: =ACTUAL!G13
B14: Incendio y Terremoto sin iva | D14: =ACTUAL!G14 | E14: TASA NOMINAL MV | H14: =+(1+H16)^(0.0833333333333333)-1
B15: VALOR CUOTA MAS SEGURO | D15: =+H19 | E15: TASA NOMINAL ANUAL MES VENCIDO | H15: =+H14*12
E16: TASA EFECTIVA ANUAL | H16: =ACTUAL!K16
B17: MES | C17: SALDO K | D17: ABONO CAPITAL | E17: VLR INTERESES | F17: VLR CUOTA SIN SEGURO | G17: SEGURO | H17: VLR CUOTA MAS SEGURO
B18: 0 | C18: =D7
B19: 1 | C19: =+IF(C18-D19<0,0,C18-D19) | D19: =F19-E19 | E19: =C18*$D$8 | F19: =IF(ROUND(C18,0)=0,0,PMT($D$8,$D$9,-$D$7)) | G19: =+IF(ROUND(C18,0)=0,0,+$D$13+$D$14) | H19: =+G19+F19
B20: 2 | C20: =+IF(C19-D20<0,0,C19-D20) | D20: =F20-E20 | E20: =C19*$D$8 | F20: =IF(ROUND(C19,0)=0,0,PMT($D$8,$D$9,-$D$7)) | G20: =+IF(ROUND(C19,0)=0,0,+$D$13+$D$14) | H20: =+G20+F20
B21: 3 | C21: =+IF(C20-D21<0,0,C20-D21) | D21: =F21-E21 | E21: =C20*$D$8 | F21: =IF(ROUND(C20,0)=0,0,PMT($D$8,$D$9,-$D$7)) | G21: =+IF(ROUND(C20,0)=0,0,+$D$13+$D$14) | H21: =+G21+F21
B22: 4 | C22: =+IF(C21-D22<0,0,C21-D22) | D22: =F22-E22 | E22: =C21*$D$8 | F22: =IF(ROUND(C21,0)=0,0,PMT($D$8,$D$9,-$D$7)) | G22: =+IF(ROUND(C21,0)=0,0,+$D$13+$D$14) | H22: =+G22+F22
B23: 5 | C23: =+IF(C22-D23<0,0,C22-D23) | D23: =F23-E23 | E23: =C22*$D$8 | F23: =IF(ROUND(C22,0)=0,0,PMT($D$8,$D$9,-$D$7)) | G23: =+IF(ROUND(C22,0)=0,0,+$D$13+$D$14) | H23: =+G23+F23
B24: 6 | C24: =+IF(C23-D24<0,0,C23-D24) | D24: =F24-E24 | E24: =C23*$D$8 | F24: =IF(ROUND(C23,0)=0,0,PMT($D$8,$D$9,-$D$7)) | G24: =+IF(ROUND(C23,0)=0,0,+$D$13+$D$14) | H24: =+G24+F24
B25: 7 | C25: =+IF(C24-D25<0,0,C24-D25) | D25: =F25-E25 | E25: =C24*$D$8 | F25: =IF(ROUND(C24,0)=0,0,PMT($D$8,$D$9,-$D$7)) | G25: =+IF(ROUND(C24,0)=0,0,+$D$13+$D$14) | H25: =+G25+F25
B26: 8 | C26: =+IF(C25-D26<0,0,C25-D26) | D26: =F26-E26 | E26: =C25*$D$8 | F26: =IF(ROUND(C25,0)=0,0,PMT($D$8,$D$9,-$D$7)) | G26: =+IF(ROUND(C25,0)=0,0,+$D$13+$D$14) | H26: =+G26+F26
B27: 9 | C27: =+IF(C26-D27<0,0,C26-D27) | D27: =F27-E27 | E27: =C26*$D$8 | F27: =IF(ROUND(C26,0)=0,0,PMT($D$8,$D$9,-$D$7)) | G27: =+IF(ROUND(C26,0)=0,0,+$D$13+$D$14) | H27: =+G27+F27
B28: 10 | C28: =+IF(C27-D28<0,0,C27-D28) | D28: =F28-E28 | E28: =C27*$D$8 | F28: =IF(ROUND(C27,0)=0,0,PMT($D$8,$D$9,-$D$7)) | G28: =+IF(ROUND(C27,0)=0,0,+$D$13+$D$14) | H28: =+G28+F28
B29: 11 | C29: =+IF(C28-D29<0,0,C28-D29) | D29: =F29-E29 | E29: =C28*$D$8 | F29: =IF(ROUND(C28,0)=0,0,PMT($D$8,$D$9,-$D$7)) | G29: =+IF(ROUND(C28,0)=0,0,+$D$13+$D$14) | H29: =+G29+F29
B30: 12 | C30: =+IF(C29-D30<0,0,C29-D30) | D30: =F30-E30 | E30: =C29*$D$8 | F30: =IF(ROUND(C29,0)=0,0,PMT($D$8,$D$9,-$D$7)) | G30: =+IF(ROUND(C29,0)=0,0,+$D$13+$D$14) | H30: =+G30+F30
... B198: 180 | C198: =+IF(C197-D198<0,0,C197-D198) | D198: =F198-E198 | E198: =C197*$D$8 | F198: =IF(ROUND(C197,0)=0,0,PMT($D$8,$D$9,-$D$7)) | G198: =+IF(ROUND(C197,0)=0,0,+$D$13+$D$14) | H198: =+G198+F198
B199: =+B198+1 | C199: =+IF(C198-D199<0,0,C198-D199) | D199: =F199-E199 | E199: =C198*$D$8 | F199: =IF(ROUND(C198,0)=0,0,PMT($D$8,$D$9,-$D$7)) | G199: =+IF(ROUND(C198,0)=0,0,+$D$13+$D$14) | H199: =+G199+F199
B200: =+B199+1 | C200: =+IF(C199-D200<0,0,C199-D200) | D200: =F200-E200 | E200: =C199*$D$8 | F200: =IF(ROUND(C199,0)=0,0,PMT($D$8,$D$9,-$D$7)) | G200: =+IF(ROUND(C199,0)=0,0,+$D$13+$D$14) | H200: =+G200+F200
B201: =+B200+1 | C201: =+IF(C200-D201<0,0,C200-D201) | D201: =F201-E201 | E201: =C200*$D$8 | F201: =IF(ROUND(C200,0)=0,0,PMT($D$8,$D$9,-$D$7)) | G201: =+IF(ROUND(C200,0)=0,0,+$D$13+$D$14) | H201: =+G201+F201
B202: =+B201+1 | C202: =+IF(C201-D202<0,0,C201-D202) | D202: =F202-E202 | E202: =C201*$D$8 | F202: =IF(ROUND(C201,0)=0,0,PMT($D$8,$D$9,-$D$7)) | G202: =+IF(ROUND(C201,0)=0,0,+$D$13+$D$14) | H202: =+G202+F202
B203: =+B202+1 | C203: =+IF(C202-D203<0,0,C202-D203) | D203: =F203-E203 | E203: =C202*$D$8 | F203: =IF(ROUND(C202,0)=0,0,PMT($D$8,$D$9,-$D$7)) | G203: =+IF(ROUND(C202,0)=0,0,+$D$13+$D$14) | H203: =+G203+F203
B204: =+B203+1 | C204: =+IF(C203-D204<0,0,C203-D204) | D204: =F204-E204 | E204: =C203*$D$8 | F204: =IF(ROUND(C203,0)=0,0,PMT($D$8,$D$9,-$D$7)) | G204: =+IF(ROUND(C203,0)=0,0,+$D$13+$D$14) | H204: =+G204+F204
B205: =+B204+1 | C205: =+IF(C204-D205<0,0,C204-D205) | D205: =F205-E205 | E205: =C204*$D$8 | F205: =IF(ROUND(C204,0)=0,0,PMT($D$8,$D$9,-$D$7)) | G205: =+IF(ROUND(C204,0)=0,0,+$D$13+$D$14) | H205: =+G205+F205
B206: =+B205+1 | C206: =+IF(C205-D206<0,0,C205-D206) | D206: =F206-E206 | E206: =C205*$D$8 | F206: =IF(ROUND(C205,0)=0,0,PMT($D$8,$D$9,-$D$7)) | G206: =+IF(ROUND(C205,0)=0,0,+$D$13+$D$14) | H206: =+G206+F206
B207: =+B206+1 | C207: =+IF(C206-D207<0,0,C206-D207) | D207: =F207-E207 | E207: =C206*$D$8 | F207: =IF(ROUND(C206,0)=0,0,PMT($D$8,$D$9,-$D$7)) | G207: =+IF(ROUND(C206,0)=0,0,+$D$13+$D$14) | H207: =+G207+F207
B208: =+B207+1 | C208: =+IF(C207-D208<0,0,C207-D208) | D208: =F208-E208 | E208: =C207*$D$8 | F208: =IF(ROUND(C207,0)=0,0,PMT($D$8,$D$9,-$D$7)) | G208: =+IF(ROUND(C207,0)=0,0,+$D$13+$D$14) | H208: =+G208+F208
B209: =+B208+1 | C209: =+IF(C208-D209<0,0,C208-D209) | D209: =F209-E209 | E209: =C208*$D$8 | F209: =IF(ROUND(C208,0)=0,0,PMT($D$8,$D$9,-$D$7)) | G209: =+IF(ROUND(C208,0)=0,0,+$D$13+$D$14) | H209: =+G209+F209
B210: =+B209+1 | C210: =+IF(C209-D210<0,0,C209-D210) | D210: =F210-E210 | E210: =C209*$D$8 | F210: =IF(ROUND(C209,0)=0,0,PMT($D$8,$D$9,-$D$7)) | G210: =+IF(ROUND(C209,0)=0,0,+$D$13+$D$14) | H210: =+G210+F210
... B378: =+B377+1 | C378: =+IF(C377-D378<0,0,C377-D378) | D378: =F378-E378 | E378: =C377*$D$8 | F378: =IF(ROUND(C377,0)=0,0,PMT($D$8,$D$9,-$D$7)) | G378: =+IF(ROUND(C377,0)=0,0,+$D$13+$D$14) | H378: =+G378+F378

Sheet PESOS  (4)
B7: VALOR PRESTAMO | D7: =ACTUAL!G7 | E7: OPCIÓN 4
B8: TASA DE INTERES MES | D8: =H14
B9: PLAZO DEL CREDITO (MESES) | D9: =ACTUAL!J10
B10: Edad Cliente | D10: 0
B11: Valor Inmueble | D11: 0
B12: Total seguros | D12: 0
B13: Seguro de Vida | D13: =ACTUAL!G13
B14: Incendio y Terremoto sin iva | D14: =ACTUAL!G14 | E14: TASA NOMINAL MV | H14: =+(1+H16)^(0.0833333333333333)-1
B15: VALOR CUOTA MAS SEGURO | D15: =+H19 | E15: TASA NOMINAL ANUAL MES VENCIDO | H15: =+H14*12
E16: TASA EFECTIVA ANUAL | H16: =ACTUAL!K16
B17: MES | C17: SALDO K | D17: ABONO CAPITAL | E17: VLR INTERESES | F17: VLR CUOTA SIN SEGURO | G17: SEGURO | H17: VLR CUOTA MAS SEGURO
B18: 0 | C18: =D7
B19: 1 | C19: =+IF(C18-D19<0,0,C18-D19) | D19: =F19-E19 | E19: =C18*$D$8 | F19: =IF(ROUND(C18,0)=0,0,PMT($D$8,$D$9,-$D$7)) | G19: =+IF(ROUND(C18,0)=0,0,+$D$13+$D$14) | H19: =+G19+F19
B20: 2 | C20: =+IF(C19-D20<0,0,C19-D20) | D20: =F20-E20 | E20: =C19*$D$8 | F20: =IF(ROUND(C19,0)=0,0,PMT($D$8,$D$9,-$D$7)) | G20: =+IF(ROUND(C19,0)=0,0,+$D$13+$D$14) | H20: =+G20+F20
B21: 3 | C21: =+IF(C20-D21<0,0,C20-D21) | D21: =F21-E21 | E21: =C20*$D$8 | F21: =IF(ROUND(C20,0)=0,0,PMT($D$8,$D$9,-$D$7)) | G21: =+IF(ROUND(C20,0)=0,0,+$D$13+$D$14) | H21: =+G21+F21
B22: 4 | C22: =+IF(C21-D22<0,0,C21-D22) | D22: =F22-E22 | E22: =C21*$D$8 | F22: =IF(ROUND(C21,0)=0,0,PMT($D$8,$D$9,-$D$7)) | G22: =+IF(ROUND(C21,0)=0,0,+$D$13+$D$14) | H22: =+G22+F22
B23: 5 | C23: =+IF(C22-D23<0,0,C22-D23) | D23: =F23-E23 | E23: =C22*$D$8 | F23: =IF(ROUND(C22,0)=0,0,PMT($D$8,$D$9,-$D$7)) | G23: =+IF(ROUND(C22,0)=0,0,+$D$13+$D$14) | H23: =+G23+F23
B24: 6 | C24: =+IF(C23-D24<0,0,C23-D24) | D24: =F24-E24 | E24: =C23*$D$8 | F24: =IF(ROUND(C23,0)=0,0,PMT($D$8,$D$9,-$D$7)) | G24: =+IF(ROUND(C23,0)=0,0,+$D$13+$D$14) | H24: =+G24+F24
B25: 7 | C25: =+IF(C24-D25<0,0,C24-D25) | D25: =F25-E25 | E25: =C24*$D$8 | F25: =IF(ROUND(C24,0)=0,0,PMT($D$8,$D$9,-$D$7)) | G25: =+IF(ROUND(C24,0)=0,0,+$D$13+$D$14) | H25: =+G25+F25
B26: 8 | C26: =+IF(C25-D26<0,0,C25-D26) | D26: =F26-E26 | E26: =C25*$D$8 | F26: =IF(ROUND(C25,0)=0,0,PMT($D$8,$D$9,-$D$7)) | G26: =+IF(ROUND(C25,0)=0,0,+$D$13+$D$14) | H26: =+G26+F26
B27: 9 | C27: =+IF(C26-D27<0,0,C26-D27) | D27: =F27-E27 | E27: =C26*$D$8 | F27: =IF(ROUND(C26,0)=0,0,PMT($D$8,$D$9,-$D$7)) | G27: =+IF(ROUND(C26,0)=0,0,+$D$13+$D$14) | H27: =+G27+F27
B28: 10 | C28: =+IF(C27-D28<0,0,C27-D28) | D28: =F28-E28 | E28: =C27*$D$8 | F28: =IF(ROUND(C27,0)=0,0,PMT($D$8,$D$9,-$D$7)) | G28: =+IF(ROUND(C27,0)=0,0,+$D$13+$D$14) | H28: =+G28+F28
B29: 11 | C29: =+IF(C28-D29<0,0,C28-D29) | D29: =F29-E29 | E29: =C28*$D$8 | F29: =IF(ROUND(C28,0)=0,0,PMT($D$8,$D$9,-$D$7)) | G29: =+IF(ROUND(C28,0)=0,0,+$D$13+$D$14) | H29: =+G29+F29
B30: 12 | C30: =+IF(C29-D30<0,0,C29-D30) | D30: =F30-E30 | E30: =C29*$D$8 | F30: =IF(ROUND(C29,0)=0,0,PMT($D$8,$D$9,-$D$7)) | G30: =+IF(ROUND(C29,0)=0,0,+$D$13+$D$14) | H30: =+G30+F30
... B198: 180 | C198: =+IF(C197-D198<0,0,C197-D198) | D198: =F198-E198 | E198: =C197*$D$8 | F198: =IF(ROUND(C197,0)=0,0,PMT($D$8,$D$9,-$D$7)) | G198: =+IF(ROUND(C197,0)=0,0,+$D$13+$D$14) | H198: =+G198+F198
B199: =+B198+1 | C199: =+IF(C198-D199<0,0,C198-D199) | D199: =F199-E199 | E199: =C198*$D$8 | F199: =IF(ROUND(C198,0)=0,0,PMT($D$8,$D$9,-$D$7)) | G199: =+IF(ROUND(C198,0)=0,0,+$D$13+$D$14) | H199: =+G199+F199
